2019-04-19 13:53:58,378 INFO:SQLAlchemy Sample [in D:\SQLAlchemy_Sample\app\__init__.py:44]
2019-04-19 13:56:14,292 ERROR:Exception on /user/a [GET] [in C:\Users\tagbi\AppData\Local\Programs\Python\Python37-32\lib\site-packages\flask\app.py:1761]
Traceback (most recent call last):
  File "C:\Users\tagbi\AppData\Local\Programs\Python\Python37-32\lib\site-packages\flask\app.py", line 2292, in wsgi_app
    response = self.full_dispatch_request()
  File "C:\Users\tagbi\AppData\Local\Programs\Python\Python37-32\lib\site-packages\flask\app.py", line 1815, in full_dispatch_request
    rv = self.handle_user_exception(e)
  File "C:\Users\tagbi\AppData\Local\Programs\Python\Python37-32\lib\site-packages\flask\app.py", line 1718, in handle_user_exception
    reraise(exc_type, exc_value, tb)
  File "C:\Users\tagbi\AppData\Local\Programs\Python\Python37-32\lib\site-packages\flask\_compat.py", line 35, in reraise
    raise value
  File "C:\Users\tagbi\AppData\Local\Programs\Python\Python37-32\lib\site-packages\flask\app.py", line 1813, in full_dispatch_request
    rv = self.dispatch_request()
  File "C:\Users\tagbi\AppData\Local\Programs\Python\Python37-32\lib\site-packages\flask\app.py", line 1799, in dispatch_request
    return self.view_functions[rule.endpoint](**req.view_args)
  File "C:\Users\tagbi\AppData\Local\Programs\Python\Python37-32\lib\site-packages\flask_login\utils.py", line 261, in decorated_view
    return func(*args, **kwargs)
  File "D:\SQLAlchemy_Sample\app\routes.py", line 81, in user
    return render_template('user.html', user=user, posts=posts)
  File "C:\Users\tagbi\AppData\Local\Programs\Python\Python37-32\lib\site-packages\flask\templating.py", line 135, in render_template
    context, ctx.app)
  File "C:\Users\tagbi\AppData\Local\Programs\Python\Python37-32\lib\site-packages\flask\templating.py", line 117, in _render
    rv = template.render(context)
  File "C:\Users\tagbi\AppData\Local\Programs\Python\Python37-32\lib\site-packages\jinja2\asyncsupport.py", line 76, in render
    return original_render(self, *args, **kwargs)
  File "C:\Users\tagbi\AppData\Local\Programs\Python\Python37-32\lib\site-packages\jinja2\environment.py", line 1008, in render
    return self.environment.handle_exception(exc_info, True)
  File "C:\Users\tagbi\AppData\Local\Programs\Python\Python37-32\lib\site-packages\jinja2\environment.py", line 780, in handle_exception
    reraise(exc_type, exc_value, tb)
  File "C:\Users\tagbi\AppData\Local\Programs\Python\Python37-32\lib\site-packages\jinja2\_compat.py", line 37, in reraise
    raise value.with_traceback(tb)
  File "D:\SQLAlchemy_Sample\app\templates\user.html", line 1, in top-level template code
    {% extends "base.html" %}
  File "D:\SQLAlchemy_Sample\app\templates\base.html", line 31, in top-level template code
    {% block content %}{% endblock %}
  File "D:\SQLAlchemy_Sample\app\templates\user.html", line 15, in block "content"
    <p><a href="{{ url_for('unfollow', username-user.username) }}">Unfollow</a> </p>
jinja2.exceptions.UndefinedError: 'username' is undefined
2019-04-19 13:56:59,721 ERROR:Exception on /user/a [GET] [in C:\Users\tagbi\AppData\Local\Programs\Python\Python37-32\lib\site-packages\flask\app.py:1761]
Traceback (most recent call last):
  File "C:\Users\tagbi\AppData\Local\Programs\Python\Python37-32\lib\site-packages\flask\app.py", line 2292, in wsgi_app
    response = self.full_dispatch_request()
  File "C:\Users\tagbi\AppData\Local\Programs\Python\Python37-32\lib\site-packages\flask\app.py", line 1815, in full_dispatch_request
    rv = self.handle_user_exception(e)
  File "C:\Users\tagbi\AppData\Local\Programs\Python\Python37-32\lib\site-packages\flask\app.py", line 1718, in handle_user_exception
    reraise(exc_type, exc_value, tb)
  File "C:\Users\tagbi\AppData\Local\Programs\Python\Python37-32\lib\site-packages\flask\_compat.py", line 35, in reraise
    raise value
  File "C:\Users\tagbi\AppData\Local\Programs\Python\Python37-32\lib\site-packages\flask\app.py", line 1813, in full_dispatch_request
    rv = self.dispatch_request()
  File "C:\Users\tagbi\AppData\Local\Programs\Python\Python37-32\lib\site-packages\flask\app.py", line 1799, in dispatch_request
    return self.view_functions[rule.endpoint](**req.view_args)
  File "C:\Users\tagbi\AppData\Local\Programs\Python\Python37-32\lib\site-packages\flask_login\utils.py", line 261, in decorated_view
    return func(*args, **kwargs)
  File "D:\SQLAlchemy_Sample\app\routes.py", line 81, in user
    return render_template('user.html', user=user, posts=posts)
  File "C:\Users\tagbi\AppData\Local\Programs\Python\Python37-32\lib\site-packages\flask\templating.py", line 135, in render_template
    context, ctx.app)
  File "C:\Users\tagbi\AppData\Local\Programs\Python\Python37-32\lib\site-packages\flask\templating.py", line 117, in _render
    rv = template.render(context)
  File "C:\Users\tagbi\AppData\Local\Programs\Python\Python37-32\lib\site-packages\jinja2\asyncsupport.py", line 76, in render
    return original_render(self, *args, **kwargs)
  File "C:\Users\tagbi\AppData\Local\Programs\Python\Python37-32\lib\site-packages\jinja2\environment.py", line 1008, in render
    return self.environment.handle_exception(exc_info, True)
  File "C:\Users\tagbi\AppData\Local\Programs\Python\Python37-32\lib\site-packages\jinja2\environment.py", line 780, in handle_exception
    reraise(exc_type, exc_value, tb)
  File "C:\Users\tagbi\AppData\Local\Programs\Python\Python37-32\lib\site-packages\jinja2\_compat.py", line 37, in reraise
    raise value.with_traceback(tb)
  File "D:\SQLAlchemy_Sample\app\templates\user.html", line 1, in top-level template code
    {% extends "base.html" %}
  File "D:\SQLAlchemy_Sample\app\templates\base.html", line 31, in top-level template code
    {% block content %}{% endblock %}
  File "D:\SQLAlchemy_Sample\app\templates\user.html", line 15, in block "content"
    <p><a href="{{ url_for('unfollow', username-user.username) }}">Unfollow</a> </p>
jinja2.exceptions.UndefinedError: 'username' is undefined
2019-04-19 13:58:12,726 ERROR:Exception on /user/b [GET] [in C:\Users\tagbi\AppData\Local\Programs\Python\Python37-32\lib\site-packages\flask\app.py:1761]
Traceback (most recent call last):
  File "C:\Users\tagbi\AppData\Local\Programs\Python\Python37-32\lib\site-packages\flask\app.py", line 2292, in wsgi_app
    response = self.full_dispatch_request()
  File "C:\Users\tagbi\AppData\Local\Programs\Python\Python37-32\lib\site-packages\flask\app.py", line 1815, in full_dispatch_request
    rv = self.handle_user_exception(e)
  File "C:\Users\tagbi\AppData\Local\Programs\Python\Python37-32\lib\site-packages\flask\app.py", line 1718, in handle_user_exception
    reraise(exc_type, exc_value, tb)
  File "C:\Users\tagbi\AppData\Local\Programs\Python\Python37-32\lib\site-packages\flask\_compat.py", line 35, in reraise
    raise value
  File "C:\Users\tagbi\AppData\Local\Programs\Python\Python37-32\lib\site-packages\flask\app.py", line 1813, in full_dispatch_request
    rv = self.dispatch_request()
  File "C:\Users\tagbi\AppData\Local\Programs\Python\Python37-32\lib\site-packages\flask\app.py", line 1799, in dispatch_request
    return self.view_functions[rule.endpoint](**req.view_args)
  File "C:\Users\tagbi\AppData\Local\Programs\Python\Python37-32\lib\site-packages\flask_login\utils.py", line 261, in decorated_view
    return func(*args, **kwargs)
  File "D:\SQLAlchemy_Sample\app\routes.py", line 81, in user
    return render_template('user.html', user=user, posts=posts)
  File "C:\Users\tagbi\AppData\Local\Programs\Python\Python37-32\lib\site-packages\flask\templating.py", line 135, in render_template
    context, ctx.app)
  File "C:\Users\tagbi\AppData\Local\Programs\Python\Python37-32\lib\site-packages\flask\templating.py", line 117, in _render
    rv = template.render(context)
  File "C:\Users\tagbi\AppData\Local\Programs\Python\Python37-32\lib\site-packages\jinja2\asyncsupport.py", line 76, in render
    return original_render(self, *args, **kwargs)
  File "C:\Users\tagbi\AppData\Local\Programs\Python\Python37-32\lib\site-packages\jinja2\environment.py", line 1008, in render
    return self.environment.handle_exception(exc_info, True)
  File "C:\Users\tagbi\AppData\Local\Programs\Python\Python37-32\lib\site-packages\jinja2\environment.py", line 780, in handle_exception
    reraise(exc_type, exc_value, tb)
  File "C:\Users\tagbi\AppData\Local\Programs\Python\Python37-32\lib\site-packages\jinja2\_compat.py", line 37, in reraise
    raise value.with_traceback(tb)
  File "D:\SQLAlchemy_Sample\app\templates\user.html", line 1, in top-level template code
    {% extends "base.html" %}
  File "D:\SQLAlchemy_Sample\app\templates\base.html", line 31, in top-level template code
    {% block content %}{% endblock %}
  File "D:\SQLAlchemy_Sample\app\templates\user.html", line 15, in block "content"
    <p><a href="{{ url_for('unfollow', username-user.username) }}">Unfollow</a> </p>
jinja2.exceptions.UndefinedError: 'username' is undefined
